<?xml version="1.0" ?>
<robot name="ayspot_a0" xmlns:xacro="http://www.ros.org/wiki/xacro">

<xacro:include filename="$(find ayspot_a0_description)/urdf/materials.xacro" />
<xacro:include filename="$(find ayspot_a0_description)/urdf/ayspot_a0.trans" />
<xacro:include filename="$(find ayspot_a0_description)/urdf/ayspot_a0.gazebo" />
<link name="base_link">
  <inertial>
    <origin rpy="0 0 0" xyz="0.0 0.0 0.0"/>
    <mass value="0.0"/>
    <inertia ixx="0.0" ixy="0.0" ixz="0.0" iyy="0.0" iyz="0.0" izz="0.0"/>
  </inertial>
  <visual>
    <origin rpy="0 0 0" xyz="0 0 0"/>
    <geometry>
      <mesh filename="package://ayspot_a0_description/meshes/base_link.stl" scale="0.001 0.001 0.001"/>
    </geometry>
    <material name="silver"/>
  </visual>
  <collision>
    <origin rpy="0 0 0" xyz="0 0 0"/>
    <geometry>
      <mesh filename="package://ayspot_a0_description/meshes/base_link.stl" scale="0.001 0.001 0.001"/>
    </geometry>
  </collision>
</link>

<link name="LH_FOOT_1">
  <inertial>
    <origin rpy="0 0 0" xyz="-0.0002326801625141539 -1.2589166095700044e-07 -0.0009015498976409075"/>
    <mass value="0.05928003994632121"/>
    <inertia ixx="1.1e-05" ixy="-0.0" ixz="0.0" iyy="1e-05" iyz="0.0" izz="1.1e-05"/>
  </inertial>
  <visual>
    <origin rpy="0 0 0" xyz="0.180726 -0.166126 0.329586"/>
    <geometry>
      <mesh filename="package://ayspot_a0_description/meshes/LH_FOOT_1.stl" scale="0.001 0.001 0.001"/>
    </geometry>
    <material name="silver"/>
  </visual>
  <collision>
    <origin rpy="0 0 0" xyz="0.180726 -0.166126 0.329586"/>
    <geometry>
      <mesh filename="package://ayspot_a0_description/meshes/LH_FOOT_1.stl" scale="0.001 0.001 0.001"/>
    </geometry>
  </collision>
</link>

<link name="RH_FOOT_1">
  <inertial>
    <origin rpy="0 0 0" xyz="-0.00040034175906467073 1.255784517761871e-07 -0.0008395510244803561"/>
    <mass value="0.05927096560645517"/>
    <inertia ixx="1.1e-05" ixy="0.0" ixz="-0.0" iyy="1e-05" iyz="-0.0" izz="1.1e-05"/>
  </inertial>
  <visual>
    <origin rpy="0 0 0" xyz="0.180521 0.166126 0.329586"/>
    <geometry>
      <mesh filename="package://ayspot_a0_description/meshes/RH_FOOT_1.stl" scale="0.001 0.001 0.001"/>
    </geometry>
    <material name="silver"/>
  </visual>
  <collision>
    <origin rpy="0 0 0" xyz="0.180521 0.166126 0.329586"/>
    <geometry>
      <mesh filename="package://ayspot_a0_description/meshes/RH_FOOT_1.stl" scale="0.001 0.001 0.001"/>
    </geometry>
  </collision>
</link>

<link name="RF_FOOT_1">
  <inertial>
    <origin rpy="0 0 0" xyz="-0.00023316300689671388 1.3078819702250222e-07 -0.0009015498976755465"/>
    <mass value="0.059280039946320986"/>
    <inertia ixx="1.1e-05" ixy="-0.0" ixz="0.0" iyy="1e-05" iyz="0.0" izz="1.1e-05"/>
  </inertial>
  <visual>
    <origin rpy="0 0 0" xyz="-0.18088 0.166126 0.329586"/>
    <geometry>
      <mesh filename="package://ayspot_a0_description/meshes/RF_FOOT_1.stl" scale="0.001 0.001 0.001"/>
    </geometry>
    <material name="silver"/>
  </visual>
  <collision>
    <origin rpy="0 0 0" xyz="-0.18088 0.166126 0.329586"/>
    <geometry>
      <mesh filename="package://ayspot_a0_description/meshes/RF_FOOT_1.stl" scale="0.001 0.001 0.001"/>
    </geometry>
  </collision>
</link>

<link name="LF_FOOT_1">
  <inertial>
    <origin rpy="0 0 0" xyz="-0.00023303833603999236 -1.2589170725330057e-07 -0.0009015498976411851"/>
    <mass value="0.059280039946321084"/>
    <inertia ixx="1.1e-05" ixy="-0.0" ixz="0.0" iyy="1e-05" iyz="0.0" izz="1.1e-05"/>
  </inertial>
  <visual>
    <origin rpy="0 0 0" xyz="-0.180796 -0.166126 0.329586"/>
    <geometry>
      <mesh filename="package://ayspot_a0_description/meshes/LF_FOOT_1.stl" scale="0.001 0.001 0.001"/>
    </geometry>
    <material name="silver"/>
  </visual>
  <collision>
    <origin rpy="0 0 0" xyz="-0.180796 -0.166126 0.329586"/>
    <geometry>
      <mesh filename="package://ayspot_a0_description/meshes/LF_FOOT_1.stl" scale="0.001 0.001 0.001"/>
    </geometry>
  </collision>
</link>

<link name="LH_HIP_1">
  <inertial>
    <origin rpy="0 0 0" xyz="-0.040510337398003166 0.0052342011369113095 -5.479076203688686e-05"/>
    <mass value="0.45945895500089107"/>
    <inertia ixx="0.000547" ixy="-5e-06" ixz="-0.0" iyy="0.000835" iyz="-0.0" izz="0.000447"/>
  </inertial>
  <visual>
    <origin rpy="0 0 0" xyz="0.1149 -0.064996 -0.000495"/>
    <geometry>
      <mesh filename="package://ayspot_a0_description/meshes/LH_HIP_1.stl" scale="0.001 0.001 0.001"/>
    </geometry>
    <material name="silver"/>
  </visual>
  <collision>
    <origin rpy="0 0 0" xyz="0.1149 -0.064996 -0.000495"/>
    <geometry>
      <mesh filename="package://ayspot_a0_description/meshes/LH_HIP_1.stl" scale="0.001 0.001 0.001"/>
    </geometry>
  </collision>
</link>

<link name="LH_THIGH_1">
  <inertial>
    <origin rpy="0 0 0" xyz="2.891827007181491e-05 0.04524393267057915 -0.013476118053667194"/>
    <mass value="0.7681754454823223"/>
    <inertia ixx="0.00206" ixy="-1e-06" ixz="1e-06" iyy="0.001852" iyz="0.000342" izz="0.001041"/>
  </inertial>
  <visual>
    <origin rpy="0 0 0" xyz="0.1807 -0.086296 -0.000495"/>
    <geometry>
      <mesh filename="package://ayspot_a0_description/meshes/LH_THIGH_1.stl" scale="0.001 0.001 0.001"/>
    </geometry>
    <material name="silver"/>
  </visual>
  <collision>
    <origin rpy="0 0 0" xyz="0.1807 -0.086296 -0.000495"/>
    <geometry>
      <mesh filename="package://ayspot_a0_description/meshes/LH_THIGH_1.stl" scale="0.001 0.001 0.001"/>
    </geometry>
  </collision>
</link>

<link name="LH_SHARK_1">
  <inertial>
    <origin rpy="0 0 0" xyz="0.006410034118920105 -2.9561081876794404e-07 -0.07012232434867471"/>
    <mass value="0.19256772036271913"/>
    <inertia ixx="0.000926" ixy="-0.0" ixz="1.3e-05" iyy="0.000942" iyz="0.0" izz="3.5e-05"/>
  </inertial>
  <visual>
    <origin rpy="0 0 0" xyz="0.180742 -0.166126 0.149559"/>
    <geometry>
      <mesh filename="package://ayspot_a0_description/meshes/LH_SHARK_1.stl" scale="0.001 0.001 0.001"/>
    </geometry>
    <material name="silver"/>
  </visual>
  <collision>
    <origin rpy="0 0 0" xyz="0.180742 -0.166126 0.149559"/>
    <geometry>
      <mesh filename="package://ayspot_a0_description/meshes/LH_SHARK_1.stl" scale="0.001 0.001 0.001"/>
    </geometry>
  </collision>
</link>

<link name="RH_HIP_1">
  <inertial>
    <origin rpy="0 0 0" xyz="-0.040510337398004165 -0.005234201136904648 5.383667308515633e-05"/>
    <mass value="0.45945895500089196"/>
    <inertia ixx="0.000547" ixy="5e-06" ixz="0.0" iyy="0.000835" iyz="-0.0" izz="0.000447"/>
  </inertial>
  <visual>
    <origin rpy="0 0 0" xyz="0.1149 0.064996 -0.000495"/>
    <geometry>
      <mesh filename="package://ayspot_a0_description/meshes/RH_HIP_1.stl" scale="0.001 0.001 0.001"/>
    </geometry>
    <material name="silver"/>
  </visual>
  <collision>
    <origin rpy="0 0 0" xyz="0.1149 0.064996 -0.000495"/>
    <geometry>
      <mesh filename="package://ayspot_a0_description/meshes/RH_HIP_1.stl" scale="0.001 0.001 0.001"/>
    </geometry>
  </collision>
</link>

<link name="RH_THIGH_1">
  <inertial>
    <origin rpy="0 0 0" xyz="-2.9707501163656058e-05 -0.045243932660683425 -0.013476118053672864"/>
    <mass value="0.7681754454823299"/>
    <inertia ixx="0.00206" ixy="-1e-06" ixz="-1e-06" iyy="0.001852" iyz="-0.000342" izz="0.001041"/>
  </inertial>
  <visual>
    <origin rpy="0 0 0" xyz="0.1807 0.086296 -0.000495"/>
    <geometry>
      <mesh filename="package://ayspot_a0_description/meshes/RH_THIGH_1.stl" scale="0.001 0.001 0.001"/>
    </geometry>
    <material name="silver"/>
  </visual>
  <collision>
    <origin rpy="0 0 0" xyz="0.1807 0.086296 -0.000495"/>
    <geometry>
      <mesh filename="package://ayspot_a0_description/meshes/RH_THIGH_1.stl" scale="0.001 0.001 0.001"/>
    </geometry>
  </collision>
</link>

<link name="RH_SHARK_1">
  <inertial>
    <origin rpy="0 0 0" xyz="0.006530762043432531 -3.893086839013016e-08 -0.07012232434872082"/>
    <mass value="0.1925677203627198"/>
    <inertia ixx="0.000926" ixy="-0.0" ixz="1.3e-05" iyy="0.000942" iyz="0.0" izz="3.5e-05"/>
  </inertial>
  <visual>
    <origin rpy="0 0 0" xyz="0.180658 0.166126 0.149559"/>
    <geometry>
      <mesh filename="package://ayspot_a0_description/meshes/RH_SHARK_1.stl" scale="0.001 0.001 0.001"/>
    </geometry>
    <material name="silver"/>
  </visual>
  <collision>
    <origin rpy="0 0 0" xyz="0.180658 0.166126 0.149559"/>
    <geometry>
      <mesh filename="package://ayspot_a0_description/meshes/RH_SHARK_1.stl" scale="0.001 0.001 0.001"/>
    </geometry>
  </collision>
</link>

<link name="LF_HIP_1">
  <inertial>
    <origin rpy="0 0 0" xyz="0.0405103373980068 0.005234201136911032 5.383667308624801e-05"/>
    <mass value="0.4594589550008923"/>
    <inertia ixx="0.000547" ixy="5e-06" ixz="-0.0" iyy="0.000835" iyz="0.0" izz="0.000447"/>
  </inertial>
  <visual>
    <origin rpy="0 0 0" xyz="-0.1149 -0.064996 -0.000495"/>
    <geometry>
      <mesh filename="package://ayspot_a0_description/meshes/LF_HIP_1.stl" scale="0.001 0.001 0.001"/>
    </geometry>
    <material name="silver"/>
  </visual>
  <collision>
    <origin rpy="0 0 0" xyz="-0.1149 -0.064996 -0.000495"/>
    <geometry>
      <mesh filename="package://ayspot_a0_description/meshes/LF_HIP_1.stl" scale="0.001 0.001 0.001"/>
    </geometry>
  </collision>
</link>

<link name="LF_THIGH_1">
  <inertial>
    <origin rpy="0 0 0" xyz="2.970750116282339e-05 0.04524393267764419 -0.013476118053666258"/>
    <mass value="0.7681754454824178"/>
    <inertia ixx="0.00206" ixy="-1e-06" ixz="1e-06" iyy="0.001852" iyz="0.000342" izz="0.001041"/>
  </inertial>
  <visual>
    <origin rpy="0 0 0" xyz="-0.1807 -0.086296 -0.000495"/>
    <geometry>
      <mesh filename="package://ayspot_a0_description/meshes/LF_THIGH_1.stl" scale="0.001 0.001 0.001"/>
    </geometry>
    <material name="silver"/>
  </visual>
  <collision>
    <origin rpy="0 0 0" xyz="-0.1807 -0.086296 -0.000495"/>
    <geometry>
      <mesh filename="package://ayspot_a0_description/meshes/LF_THIGH_1.stl" scale="0.001 0.001 0.001"/>
    </geometry>
  </collision>
</link>

<link name="LF_SHARK_1">
  <inertial>
    <origin rpy="0 0 0" xyz="0.006531675945394139 -2.956108652307776e-07 -0.07012232434867488"/>
    <mass value="0.19256772036272068"/>
    <inertia ixx="0.000926" ixy="-0.0" ixz="1.3e-05" iyy="0.000942" iyz="0.0" izz="3.5e-05"/>
  </inertial>
  <visual>
    <origin rpy="0 0 0" xyz="-0.180658 -0.166126 0.149559"/>
    <geometry>
      <mesh filename="package://ayspot_a0_description/meshes/LF_SHARK_1.stl" scale="0.001 0.001 0.001"/>
    </geometry>
    <material name="silver"/>
  </visual>
  <collision>
    <origin rpy="0 0 0" xyz="-0.180658 -0.166126 0.149559"/>
    <geometry>
      <mesh filename="package://ayspot_a0_description/meshes/LF_SHARK_1.stl" scale="0.001 0.001 0.001"/>
    </geometry>
  </collision>
</link>

<link name="RF_HIP_1">
  <inertial>
    <origin rpy="0 0 0" xyz="0.04051033739800672 -0.005234201136911379 -5.4790762038312425e-05"/>
    <mass value="0.4594589550008918"/>
    <inertia ixx="0.000547" ixy="-5e-06" ixz="0.0" iyy="0.000835" iyz="0.0" izz="0.000447"/>
  </inertial>
  <visual>
    <origin rpy="0 0 0" xyz="-0.1149 0.064996 -0.000495"/>
    <geometry>
      <mesh filename="package://ayspot_a0_description/meshes/RF_HIP_1.stl" scale="0.001 0.001 0.001"/>
    </geometry>
    <material name="silver"/>
  </visual>
  <collision>
    <origin rpy="0 0 0" xyz="-0.1149 0.064996 -0.000495"/>
    <geometry>
      <mesh filename="package://ayspot_a0_description/meshes/RF_HIP_1.stl" scale="0.001 0.001 0.001"/>
    </geometry>
  </collision>
</link>

<link name="RF_THIGH_1">
  <inertial>
    <origin rpy="0 0 0" xyz="-2.8918270062378015e-05 -0.045243932660695554 -0.013476118053676234"/>
    <mass value="0.7681754454823692"/>
    <inertia ixx="0.00206" ixy="-1e-06" ixz="-1e-06" iyy="0.001852" iyz="-0.000342" izz="0.001041"/>
  </inertial>
  <visual>
    <origin rpy="0 0 0" xyz="-0.1807 0.086296 -0.000495"/>
    <geometry>
      <mesh filename="package://ayspot_a0_description/meshes/RF_THIGH_1.stl" scale="0.001 0.001 0.001"/>
    </geometry>
    <material name="silver"/>
  </visual>
  <collision>
    <origin rpy="0 0 0" xyz="-0.1807 0.086296 -0.000495"/>
    <geometry>
      <mesh filename="package://ayspot_a0_description/meshes/RF_THIGH_1.stl" scale="0.001 0.001 0.001"/>
    </geometry>
  </collision>
</link>

<link name="RF_SHARK_1">
  <inertial>
    <origin rpy="0 0 0" xyz="0.006531551274537695 -3.893094452367407e-08 -0.07012232434870974"/>
    <mass value="0.19256772036272052"/>
    <inertia ixx="0.000926" ixy="-0.0" ixz="1.3e-05" iyy="0.000942" iyz="0.0" izz="3.5e-05"/>
  </inertial>
  <visual>
    <origin rpy="0 0 0" xyz="-0.180742 0.166126 0.149559"/>
    <geometry>
      <mesh filename="package://ayspot_a0_description/meshes/RF_SHARK_1.stl" scale="0.001 0.001 0.001"/>
    </geometry>
    <material name="silver"/>
  </visual>
  <collision>
    <origin rpy="0 0 0" xyz="-0.180742 0.166126 0.149559"/>
    <geometry>
      <mesh filename="package://ayspot_a0_description/meshes/RF_SHARK_1.stl" scale="0.001 0.001 0.001"/>
    </geometry>
  </collision>
</link>

<joint name="LH_FOOT_rigid" type="fixed">
  <origin rpy="0 0 0" xyz="1.6e-05 0.0 -0.180027"/>
  <parent link="LH_SHARK_1"/>
  <child link="LH_FOOT_1"/>
</joint>

<joint name="RH_FOOT_rigid" type="fixed">
  <origin rpy="0 0 0" xyz="0.000137 0.0 -0.180027"/>
  <parent link="RH_SHARK_1"/>
  <child link="RH_FOOT_1"/>
</joint>

<joint name="RF_FOOT_rigid" type="fixed">
  <origin rpy="0 0 0" xyz="0.000138 0.0 -0.180027"/>
  <parent link="RF_SHARK_1"/>
  <child link="RF_FOOT_1"/>
</joint>

<joint name="LF_FOOT_rigid" type="fixed">
  <origin rpy="0 0 0" xyz="0.000138 0.0 -0.180027"/>
  <parent link="LF_SHARK_1"/>
  <child link="LF_FOOT_1"/>
</joint>

<joint name="LH_HIP_rotate" type="continuous">
  <origin rpy="0 0 0" xyz="-0.1149 0.064996 0.000495"/>
  <parent link="base_link"/>
  <child link="LH_HIP_1"/>
  <axis xyz="1.0 0.0 0.0"/>
</joint>

<joint name="LH_THIGH_rotate" type="continuous">
  <origin rpy="0 0 0" xyz="-0.0658 0.0213 0.0"/>
  <parent link="LH_HIP_1"/>
  <child link="LH_THIGH_1"/>
  <axis xyz="0.0 1.0 0.0"/>
</joint>

<joint name="LH_SHARK_rotate" type="continuous">
  <origin rpy="0 0 0" xyz="-4.2e-05 0.07983 -0.150054"/>
  <parent link="LH_THIGH_1"/>
  <child link="LH_SHARK_1"/>
  <axis xyz="0.0 1.0 0.0"/>
</joint>

<joint name="RH_HIP_rotate" type="continuous">
  <origin rpy="0 0 0" xyz="-0.1149 -0.064996 0.000495"/>
  <parent link="base_link"/>
  <child link="RH_HIP_1"/>
  <axis xyz="1.0 0.0 0.0"/>
</joint>

<joint name="RH_THIGH_rotate" type="continuous">
  <origin rpy="0 0 0" xyz="-0.0658 -0.0213 0.0"/>
  <parent link="RH_HIP_1"/>
  <child link="RH_THIGH_1"/>
  <axis xyz="0.0 1.0 0.0"/>
</joint>

<joint name="RH_SHARK_rotate" type="continuous">
  <origin rpy="0 0 0" xyz="4.2e-05 -0.07983 -0.150054"/>
  <parent link="RH_THIGH_1"/>
  <child link="RH_SHARK_1"/>
  <axis xyz="0.0 1.0 0.0"/>
</joint>

<joint name="LF_HIP_rotate" type="continuous">
  <origin rpy="0 0 0" xyz="0.1149 0.064996 0.000495"/>
  <parent link="base_link"/>
  <child link="LF_HIP_1"/>
  <axis xyz="1.0 0.0 0.0"/>
</joint>

<joint name="LF_THIGH_roate" type="continuous">
  <origin rpy="0 0 0" xyz="0.0658 0.0213 0.0"/>
  <parent link="LF_HIP_1"/>
  <child link="LF_THIGH_1"/>
  <axis xyz="-0.0 1.0 0.0"/>
</joint>

<joint name="LF_SHARK_rotate" type="continuous">
  <origin rpy="0 0 0" xyz="-4.2e-05 0.07983 -0.150054"/>
  <parent link="LF_THIGH_1"/>
  <child link="LF_SHARK_1"/>
  <axis xyz="0.0 1.0 0.0"/>
</joint>

<joint name="RF_HIP_rorate" type="continuous">
  <origin rpy="0 0 0" xyz="0.1149 -0.064996 0.000495"/>
  <parent link="base_link"/>
  <child link="RF_HIP_1"/>
  <axis xyz="1.0 0.0 0.0"/>
</joint>

<joint name="RF_THIGH_rotate" type="continuous">
  <origin rpy="0 0 0" xyz="0.0658 -0.0213 0.0"/>
  <parent link="RF_HIP_1"/>
  <child link="RF_THIGH_1"/>
  <axis xyz="0.0 1.0 0.0"/>
</joint>

<joint name="RF_SHARK_rotate" type="continuous">
  <origin rpy="0 0 0" xyz="4.2e-05 -0.07983 -0.150054"/>
  <parent link="RF_THIGH_1"/>
  <child link="RF_SHARK_1"/>
  <axis xyz="0.0 1.0 0.0"/>
</joint>

</robot>
